Workbook

Sheet Financial Stmt_As per SCH-III
H1: =+F29-F46 -> 0 | I1: =+G29-G46 -> 0
A2: HI DIAMONDS PVT. LTD.
A3: G-1, DIL PASAND SQUARE , 164, KANCHAN BAG , INDORE
A4: BALANCE SHEET AS AT | E4: 31st March, 2025
A5: CIN U52393MP2010PTC024277
A6: Particulars | E6: Note No. | F6: Figures as at the end of current reporting period 31-03-2025 | G6: Figures as at the end of current reporting period 31-03-2024
F7: Amount (In Rs.) | G7: Amount (In Rs.)
A8: I. EQUITY AND LIABILITIES
J9: 24-25 | K9: 23-24 | L9: 22-23
A10: Shareholders' Fund | I10: nws | J10: =+F45-F28 -> 79975606 | K10: =+G45-G28 -> 75513134 | L10: 71855823
A11: Share Capital | E11: =A173 -> 3 | F11: =+F187 -> 3000000 | G11: =+G187 -> 3000000 | J11: =+J10+K10 -> 1.5548874e+08 | K11: =+K10+L10 -> 1.4736896e+08
A12: Reserves & Surplus | E12: =A216 -> 4 | F12: =+F233 -> 211792.51 | G12: =+G233 -> 41317 | I12: avg wc | J12: =+J11/2 -> 77744370 | K12: =+K11/2 -> 73684478
F14: =SUM(F11:F12) -> 3211792.5 | G14: =SUM(G11:G12) -> 3041317 | H14: 2754419.1
A15: Share application money, pending allotment
A17: Non-current liabilities
A18: Long-term borrowings | E18: =A236 -> 5 | F18: =D251 -> 77374997 | G18: =E251 -> 73150310
A19: Deferred tax liabilities(Net) | E19: =A272 -> 6 | F19: 0 | G19: =IF(G282>0,G282,0) -> 0
F20: =SUM(F18:F19) -> 77374997 | G20: =SUM(G18:G19) -> 73150310
A21: Current liabilities
A22: Short-term borrowings | E22: =A285 -> 7 | F22: =+F292 -> 654705 | G22: =+G292 -> 752605.29
A23: Trade Payables
B24: (A) total outstading dues of Micro enterprises and small enterprises | E24: =A298 -> 8 | F24: =+G302 -> 0 | G24: =+G310 -> 0 | H24: 0
B25: (B) total outstanding dues of creditors other than micro enterprises and small enterprises | F25: =+G303 -> 1901469 | G25: =+G311 -> 3210699.7 | H25: 2365142.5
A26: Other current liabilities | E26: =A314 -> 9 | F26: =F331 -> 1827622.7 | G26: =G331 -> 877050
A27: Short term provisions | E27: =A334 -> 10 | F27: =+F338 -> 14679 | G27: =+G338 -> 49580
F28: =SUM(F21:F27) -> 4398475.7 | G28: =SUM(G21:G27) -> 4889935
A29: TOTAL | F29: =+F28+F20+F14 -> 84985265 | G29: =+G28+G20+G14 -> 81081562
A30: II. ASSETS
A31: Non-current assets
A32: Property, Plant Equipment and Intangible assets | E32: =+E27+1 -> 11 | F32: ='Dep. SCH'!L32 -> 565757.97 | G32: ='Dep. SCH'!M32 -> 631853.75
A33: Prperty, plant and equipments
A34: Intangible assets
A35: Long-term loans and advances | E35: =+E32+1 -> 12 | F35: =+F348 -> 0 | G35: =+G348 -> 0
A36: Other non-current assets | E36: =A351 -> 13 | F36: =F362 -> 45425 | G36: =G362 -> 46639
F37: =SUM(F31:F36) -> 611182.97 | G37: =SUM(G31:G36) -> 678492.75
A38: Current assets
A39: Inventories | E39: =A364 -> 14 | F39: =F374 -> 75322850 | G39: =G374 -> 71260850 | H39: 66380400
A40: Trade Receivables | E40: =A391 -> 15 | F40: =G402 -> 7947879 | G40: =G412 -> 8002329 | H40: 7947879
A41: Cash and bank balances
A42: Cash and cash equivelants | E42: =A415 -> 16 | F42: =F419 -> 438801.88 | G42: =G419 -> 519160.16
...

Sheet MAT and Diff
B2: TAX LIABILITY U/S 115 JB | G2: IT | H2: As per Books
B3: 2012-13 | F3: Gross | G3: =2772741+12500+251770 -> 3037011 | H3: 8212446
F4: Dep | G4: 408556 | H4: 6569947.3 | K4: DTA
B5: income | D5: ='Financial Stmt_As per SCH-III'!F80 -> 202475.51 | F5: Net | G5: =+G3-G4 -> 2628455 | H5: =+H3-H4 -> 1642498.7 | J5: =+H5-G5 -> -985956.3 | K5: =+J5*0.3 -> -295786.89
B7: adjsutment | D7: 0
B9: book profit | D9: =+D5-D7 -> 202475.51
B11: mat | D11: =IF(D9>0,D9*0.15,0) -> 30371.327
B12: sc | D12: 0
B13: total | D13: =+D11+D12 -> 30371.327
B15: ed cess | D15: =+D13*0.04 -> 1214.8531
B17: total tax | D17: =+D13+D15 -> 31586.18
B19: advance tax | D19: 0
B21: net | D21: =+D17-D19 -> 31586.18
A26: Deffred Tax libilites | E26: 37570 | G26: DTA
B28: WDV as per IT Act | E28: 1843303.9 | G28: =+G5 -> 2628455
B29: WDV as per Copmanies Act | E29: ='Dep. SCH'!L26 -> 565757.97 | G29: =+H5 -> 1642498.7
B31: Difference | E31: =E29-E28 -> -1277545.9 | G31: =G29-G28 -> -985956.3
B33: Tax | E33: =+E31*0.25 -> -319386.48 | G33: =+G31*0.25 -> -246489.07
B34: Sc | E34: 0 | G34: 0
B35: Cess | E35: =+(E33+E34)*0.04 -> -12775.459 | G35: =+(G33+G34)*0.03 -> -7394.6722
B37: Total liabilites | E37: =SUM(E33:E36) -> -332161.94 | G37: =SUM(G33:G36) -> -253883.75
B39: assets | E39: 94596 | G39: 0
B40: tax | E40: =+E39*0.25 -> 23649 | G40: =+G39*0.3 -> 0
B41: cess | E41: =+E40*0.04 -> 945.96 | G41: =+G40*0.02 -> 0
B42: assets | E42: =+E40+E41 -> 24594.96 | G42: =+G40+G41 -> 0
B43: net liablity | E43: =+E37-E42 -> -356756.9 | G43: =+G37-G42 -> -253883.75
B45: Cl. Bal | E45: 0 | F45: 130000 | G45: 253884
F46: =+F45-E45 -> 130000
B47: to be provided | E47: =+E43-E45 -> -356756.9
D51: INCOM TAX LIABILITY
B53: PROFIT | E53: =+'Financial Stmt_As per SCH-III'!F90 -> 170475.51
A54: ADD | B54: DEP AS PER BOOKS | E54: =+'Dep. SCH'!I26 -> 80163.58
E57: =+E53+E54 -> 250639.09
A58: LESS | B58: DEP AS PER IT | E58: 389673
B59: c/f loss | E59: 60695
B60: NET PROFT AS PER IT | E60: =+E57-E58-E59 -> -199728.91
B62: TAX | E62: =+E60*0.25 -> -49932.227
B63: EC | E63: =+E62*0.04 -> -1997.2891
B64: TOTAL TAX | E64: =+E62+E63 -> -51929.517

Sheet Dep. SCH
A2: ='Financial Stmt_As per SCH-III'!A2 -> HI DIAMONDS PVT. LTD.
A3: =+'Financial Stmt_As per SCH-III'!E32 -> 11 | B3: Property, plant and Equipments | C3: Gross Block | H3: Deprication | L3: Net Block
A4: PARTICULARS | C4: As at | D4: Addition | E4: Sales | F4: Subsidy | G4: As at | H4: Upto | I4: For the | J4: Deduction | K4: Upto | L4: As at | M4: As at
C5: 01.04.2024 | G5: 31.03.2025 | H5: =C5 -> 01.04.2024 | I5: Year | K5: =G5 -> 31.03.2025 | L5: =G5 -> 31.03.2025 | M5: =C5 -> 01.04.2024
A7: Lease Hold Land | C7: 0 | D7: 0 | E7: 0 | F7: 0 | G7: =+C7+D7-E7-F7 -> 0 | H7: 0 | I7: 0 | J7: 0 | K7: =H7+I7-J7 -> 0 | L7: =+G7-K7 -> 0 | M7: =+C7-H7 -> 0
A8: I Buildings
A9: Factory Building | C9: 0 | D9: 0 | E9: 0 | F9: 0 | G9: =+C9+D9-E9-F9 -> 0 | H9: 0 | I9: 0 | J9: 0 | K9: =H9+I9-J9 -> 0 | L9: =+G9-K9 -> 0 | M9: =+C9-H9 -> 0
A10: Other Building | C10: 111931 | D10: 0 | E10: 0 | F10: 0 | G10: =+C10+D10-E10-F10 -> 111931 | H10: 44571 | I10: 3464.62 | J10: 0 | K10: =H10+I10-J10 -> 48035.62 | L10: =+G10-K10 -> 63895.38 | M10: =+C10-H10 -> 67360
A11: Residential building | C11: 0 | D11: 0 | E11: 0 | F11: 0 | G11: =+C11+D11-E11-F11 -> 0 | H11: 0 | I11: 0 | J11: 0 | K11: =H11+I11-J11 -> 0 | L11: =+G11-K11 -> 0 | M11: =+C11-H11 -> 0
A12: II Plant and Machinery
A13: Plant and Machinery | C13: 0 | D13: 0 | E13: 0 | F13: 0 | G13: =+C13+D13-E13-F13 -> 0 | H13: 0 | I13: 0 | J13: 0 | K13: =H13+I13-J13 -> 0 | L13: =+G13-K13 -> 0 | M13: =+C13-H13 -> 0
A14: Solar Plant | C14: 0 | D14: 0 | E14: 0 | F14: 0 | G14: 0 | H14: 0 | I14: 0 | J14: 0 | K14: =H14+I14-J14 -> 0 | L14: =+G14-K14 -> 0 | M14: =+C14-H14 -> 0
A15: Power Saving Equipments
A16: Electrical Installations | C16: 747283 | D16: 0 | E16: 0 | F16: 0 | G16: =+C16+D16-E16-F16 -> 747283 | H16: 620689 | I16: 54191.59 | J16: 0 | K16: =H16+I16-J16 -> 674880.59 | L16: =+G16-K16 -> 72402.41 | M16: =+C16-H16 -> 126594
A17: Laboratory Equipments
A18: III Furniture and Fixtures
A19: Furnitures and Fixtures | C19: 1426601 | D19: 0 | E19: 0 | F19: 0 | G19: =+C19+D19-E19-F19 -> 1426601 | H19: 1355270 | I19: 0 | J19: 0 | K19: =H19+I19-J19 -> 1355270 | L19: =+G19-K19 -> 71331 | M19: =+C19-H19 -> 71331
A20: IV Vehicles
A21: Car and other Vehicles | C21: 5290419 | D21: 0 | E21: 0 | F21: 0 | G21: =+C21+D21-E21-F21 -> 5290419 | H21: 5025896 | I21: 0 | J21: 0 | K21: =H21+I21-J21 -> 5025896 | L21: =+G21-K21 -> 264523 | M21: =+C21-H21 -> 264523
A22: Scooter
A23: V Office Equipments
A24: Office Equipments | C24: 443010.75 | D24: 14067.8 | E24: 0 | F24: 0 | G24: =+C24+D24-E24-F24 -> 457078.55 | H24: 350317 | I24: 18696.61 | J24: 0 | K24: =H24+I24-J24 -> 369013.61 | L24: =+G24-K24 -> 88064.94 | M24: =+C24-H24 -> 92693.75 | R24: Additions
A25: Computers | C25: 33934 | D25: 0 | E25: 0 | F25: 0 | G25: =+C25+D25-E25-F25 -> 33934 | H25: 24582 | I25: 3810.76 | J25: 0 | K25: =H25+I25-J25 -> 28392.76 | L25: =+G25-K25 -> 5541.24 | M25: =+C25-H25 -> 9352 | R25: Mobile and office
A26: Total (A) | C26: =SUM(C7:C25) -> 8053178.8 | D26: =SUM(D7:D25) -> 14067.8 | E26: =SUM(E7:E25) -> 0 | F26: =SUM(F7:F25) -> 0 | G26: =SUM(G7:G25) -> 8067246.5 | H26: =SUM(H7:H25) -> 7421325 | I26: =SUM(I7:I25) -> 80163.58 | J26: =SUM(J7:J25) -> 0 | ... M26: =SUM(M7:M25) -> 631853.75
A27: Previous Year | C27: 7960676 | D27: 92502.75 | E27: 0 | F27: 0 | G27: =C27+D27-E27-F27 -> 8053178.8 | H27: 7345807 | I27: 75518 | J27: 0 | K27: =+H27+I27-J27 -> 7421325 | L27: =+G27-K27 -> 631853.75 | M27: =+C27-H27 -> 614869
A29: CAPITAL WORK IN PROGRESS | C29: 0 | D29: 0 | E29: 0 | F29: 0 | G29: =+C29+D29-E29-F29 -> 0 | H29: 0 | I29: 0 | J29: 0 | K29: 0 | L29: 0 | M29: 0
A30: Total (B) | C30: =SUM(C29) -> 0 | D30: =SUM(D29) -> 0 | E30: =SUM(E29) -> 0 | F30: =SUM(F29) -> 0 | G30: =SUM(G29) -> 0 | H30: =SUM(H29) -> 0 | I30: =SUM(I29) -> 0 | J30: =SUM(J29) -> 0 | ... M30: =SUM(M29) -> 0
A31: Previous Year | C31: 0 | D31: 0 | E31: 0 | F31: 0 | G31: =+C31+D31-E31-F31 -> 0 | H31: 0 | I31: 0 | J31: 0 | K31: 0 | L31: =+G31-K31 -> 0 | M31: =+C31-H31 -> 0
A32: Grand Total (Current Year) A+B | C32: =+C30+C26 -> 8053178.8 | D32: =+D30+D26 -> 14067.8 | E32: =+E30+E26 -> 0 | G32: =+G30+G26 -> 8067246.5 | H32: =+H30+H26 -> 7421325 | I32: =+I30+I26 -> 80163.58 | J32: =+J30+J26 -> 0 | K32: =+K30+K26 -> 7501488.6 | L32: =+L30+L26 -> 565757.97 | M32: =+M30+M26 -> 631853.75
A33: Grand Total (Previous Year) A+B | C33: =+C27+C31 -> 7960676 | D33: =+D27+D31 -> 92502.75 | E33: =+E27+E31 -> 0 | F33: =+F27+F31 -> 0 | G33: =+G27+G31 -> 8053178.8 | H33: =+H27+H31 -> 7345807 | I33: =+I27+I31 -> 75518 | J33: =+J27+J31 -> 0 | ... M33: =+M27+M31 -> 614869

Sheet trding
F2: trafing a/c
D3: gross profit
D5: op stock | F5: ='Financial Stmt_As per SCH-III'!G39 -> 71260850 | G5: sales | I5: ='Financial Stmt_As per SCH-III'!F66 -> 39062200
D6: puracahses | F6: ='Financial Stmt_As per SCH-III'!F72 -> 36146528 | G6: cl stock | I6: ='Financial Stmt_As per SCH-III'!F39 -> 75322850
D8: Gorss Profit | F8: =+F10-SUM(F5:F7) -> 6977671.7
F10: =+I10 -> 114385050 | I10: =SUM(I5:I8) -> 114385050
